Workbook

Sheet Carátula
A1: 0
D8: UDB LEGISLACIÓN Y ECONOMÍA
D10: Economía
D11: Plan de Negocios
D15: Legajo | E15: Apellido | F15: Nombres
D17: 222789-7 | E17: Volders | F17: Matias
D18: 166298-3 | E18: Sanchez | F18: Agustín
D19: 228583-6 | E19: Pedroza | F19: Maria
D20: 159106-0 | E20: Abram Lujan | F20: Nicolas
D21: 152222-0 | E21: Paco Olmedo | F21: Jhon Daniel
D22: 204532-1 | E22: Pugliese | F22: Lautaro
D27: Grupo N° | E27: 2
D28: Docente | E28: Tomás Ignacio Cocconi
D29: Aux Docente | E29: Mía Zambrana
D30: Curso | E30: Z3051
D31: Año | E31: 2026

Sheet Consideraciones
C3: Consideraciones Generales
C5: Tasa Bancaria Activa | D5: 0.4 | E5: Es la tasa que cobra el banco por prestar dinero
C6: Tasa Bancaria Pasiva | D6: 0.26 | E6: Es la tasa que paga el banco por aceptar depositos
C7: Tasa de oportunidad de los socios | D7: 0.35 | E7: Es lo que quieren ganar los socios.
C8: Dias por mes Fabricación | D8: 21
C9: Dias por mes Administración | D9: 21
C10: Meses por año | D10: 12
C11: Dias del año | D11: 365
C12: Horas laborables diarias FAB | D12: 8
C13: Horas laborables diarias ADM | D13: 8
C14: Inflación anual | D14: 0
C15: Impuesto a los Ingresos Brutos | D15: 0.045
C16: IVA | D16: 0.21
C17: Impuesto a las Ganancias | D17: 0.35
C18: Cargas Sociales | D18: 0.6
C21: Celdas con Formulas no editables
C22: Celdas editables

Sheet Mercado
C3: Mercado
C5: Nombre del Mercado Potencial (1) | E5: Mercado Potencial (Q) | F5: Mercado Meta (2) (%) | G5: Mercado Meta (Q) | I5: Ventas destinadas al mercado Mayorista (%) | J5: Ventas destinadas al mercado Minorista (%) | K5: Total (%)
C6: Compradores de termos | E6: 4000000 | F6: 0.001 | G6: =E6*F6 -> 4000 | I6: 0.3 | J6: 0.7 | K6: =I6+J6 -> 1
C9: Mix de Productos
C10: Nombre del Producto | E10: Cantidad Vendida | F10: Precio de Venta Minorista | G10: Precio de Venta Mayorista | H10: % Participación por producto
C11: Termo electronico modelo 1 | E11: =G6 -> 4000 | F11: 165000 | G11: 150000 | H11: 1 | I11: Estos valores lo pueden editar
C12: - | H12: =+E12/$E$19 -> 0 | I12: Estos valores lo pueden editar
C13: - | H13: =+E13/$E$19 -> 0
C14: - | H14: =+E14/$E$19 -> 0
C15: - | H15: =+E15/$E$19 -> 0
C16: - | H16: =+E16/$E$19 -> 0
C17: - | H17: =+E17/$E$19 -> 0
C18: - | H18: =+E18/$E$19 -> 0
E19: =G6 -> 4000 | F19: =AVERAGE(F11:F12) -> 165000 | G19: =AVERAGE(G11:G12) -> 150000 | H19: =+IF(G6-E19<>0,"La cantidad vendida debe ser igual a la cantidad de mercado meta","")
F20: Calcular promedio ponderado de precios
C22: Vida Util | D22: Precio de Venta Mayorista | E22: Precio de Venta Minorista | F22: MIX de Precios | G22: Crecimiento del mercado acumulado | H22: Cantidad Vendida acumulado | I22: Capacidad instalada acumulada
C23: 1 | D23: =+G19 -> 150000 | E23: =+F19 -> 165000 | F23: =(E23* 0.7) + (D23* 0.3) -> 160500 | G23: 0.25 | H23: =$G$6*G23 -> 1000 | I23: =+H23/$G$6 -> 0.25
C24: 2 | D24: =+D23*(1+Consideraciones!$D$14) -> 150000 | E24: =+E23*(1+Consideraciones!$D$14) -> 165000 | F24: =(E24* 0.7) + (D24* 0.3) -> 160500 | G24: 0.35 | H24: =$G$6*G24 -> 1400 | I24: =+H24/$G$6 -> 0.35
C25: 3 | D25: =+D24*(1+Consideraciones!$D$14) -> 150000 | E25: =+E24*(1+Consideraciones!$D$14) -> 165000 | F25: =(E25* 0.7) + (D25* 0.3) -> 160500 | G25: 0.5 | H25: =$G$6*G25 -> 2000 | I25: =+H25/$G$6 -> 0.5
C26: 4 | D26: =+D25*(1+Consideraciones!$D$14) -> 150000 | E26: =+E25*(1+Consideraciones!$D$14) -> 165000 | F26: =(E26* 0.7) + (D26* 0.3) -> 160500 | G26: 0.7 | H26: =$G$6*G26 -> 2800 | I26: =+H26/$G$6 -> 0.7
C27: 5 | D27: =+D26*(1+Consideraciones!$D$14) -> 150000 | E27: =+E26*(1+Consideraciones!$D$14) -> 165000 | F27: =(E27* 0.7) + (D27* 0.3) -> 160500 | G27: 1 | H27: =$G$6*G27 -> 4000 | I27: =+H27/$G$6 -> 1
H28: =+IF(H27>G6,"Cantidad a vender mayor al mercado meta","")
C30: Definiciones Básicas
C32: (1) Mercado potencial: Es el mercado donde se encuentra instalado nuestro producto o servicio
C33: (2) Mercado meta: es parte del mercado potencial o disponible que la empresa decide captar

Sheet Amortización Muebles y Utiles
C3: Amortización Muebles y Utiles | I3: Detalle de las muebles y útiles
C5: Valor inicial | D5: =+M16 -> 5780000 | F5: Vida Util : 10 Años | I5: Cantidad | J5: Tipo de mueble | K5: Valor unitario incial | L5: Valor unitario final | M5: Valor inicial Total | N5: Valor final Total
C6: Valor Final | D6: =N16 -> 912000 | F6: Cant de cuotas | G6: =(COUNT(C10:C14)*(COUNT(C10:C14)+1))/2 -> 15 | I6: 10 | J6: Escritorios | K6: 150000 | L6: 30000 | M6: =K6*I6 -> 1500000 | N6: =L6*I6 -> 300000 | O6: https://www.easy.com.ar/escritorio-79x135x44-5cm-mdf-y-polipropileno-negro-y-natural-minimalista-midtown-1/p
C7: Valor amortizable | D7: =+D5-D6 -> 4868000 | I7: 12 | J7: Sillas de oficina | K7: 140000 | L7: 20000 | M7: =K7*I7 -> 1680000 | N7: =L7*I7 -> 240000 | O7: https://www.easy.com.ar/sillon-barkley-decototale-mesh-negro/p | Z7: Creciente
I8: 2 | J8: Mesa de trabajo técnico CAD | K8: 450000 | L8: 50000 | M8: =K8*I8 -> 900000 | N8: =L8*I8 -> 100000 | O8: https://www.mercadolibre.com.ar/mesa-dibujo-tecnico-plantec-tablero-paralelabandeja-80x120/up/MLAU303784928?pdp_filters=item_id%3AMLA900269616&matt_tool=89488245#origin=share&sid=share&wid=MLA900269616&action=copy | Z8: Decreciente
C9: Cuota Número | D9: Valor Amortizable | E9: Decreciente | F9: Valor Cuota | G9: Valor Residual por Cuota | I9: 1 | J9: Mesa de reuniones / Directorio | K9: 400000 | L9: 80000 | M9: =K9*I9 -> 400000 | N9: =L9*I9 -> 80000 | O9: https://allianiweb.com.ar/product/mesa-linea-aria-oval/ | Z9: Lineal
C10: 1 | D10: =$D$7 -> 4868000 | E10: =IF($E$9="Definir sistema",0,IF($E$9="Lineal",$C$10/5,IF($E$9="Decreciente",C14/$G$6,C10/$G$6))) -> 0.33333333 | F10: =D10*E10 -> 1622666.7 | G10: =D5-F10 -> 4157333.3 | I10: 4 | J10: Archiveros de oficina | K10: 200000 | L10: 30000 | M10: =K10*I10 -> 800000 | N10: =L10*I10 -> 120000 | O10: https://www.mercadolibre.com.ar/mueble-archivo-fichero-para-oficina-2-cajones-metal/up/MLAU3564689807?pdp_filters=item_id%3AMLA1585528059&matt_tool=89488245#origin=share&sid=share&wid=MLA1585528059&action=copy | Z10: DEFINIR SISTEMA
C11: =C10+1 -> 2 | D11: =+D10 -> 4868000 | E11: =IF($E$9="Definir sistema",0,IF($E$9="Lineal",$C$10/5,IF($E$9="Decreciente",C13/$G$6,C11/$G$6))) -> 0.26666667 | F11: =D11*E11 -> 1298133.3 | G11: =D5-F10-F11 -> 2859200 | I11: 2 | J11: Mesas para comedor / breakroom | K11: 250000 | L11: 36000 | M11: =K11*I11 -> 500000 | N11: =L11*I11 -> 72000 | O11: https://www.easy.com.ar/mesa-de-comedor-bahia-140x80x75-cm-melamina-blanco-dakot/p
C12: =C11+1 -> 3 | D12: =+D11 -> 4868000 | E12: =IF($E$9="Definir sistema",0,IF($E$9="Lineal",$C$10/5,IF($E$9="Decreciente",C12/$G$6,C12/$G$6))) -> 0.2 | F12: =D12*E12 -> 973600 | G12: =D5-F10-F11-F12 -> 1885600 | M12: =K12*I12 -> 0 | N12: =L12*I12 -> 0
C13: =C12+1 -> 4 | D13: =+D12 -> 4868000 | E13: =IF($E$9="Definir sistema",0,IF($E$9="Lineal",$C$10/5,IF($E$9="Decreciente",C11/$G$6,C13/$G$6))) -> 0.13333333 | F13: =D13*E13 -> 649066.67 | G13: =D5-F10-F11-F12-F13 -> 1236533.3 | M13: =K13*I13 -> 0 | N13: =L13*I13 -> 0
C14: =C13+1 -> 5 | D14: =+D13 -> 4868000 | E14: =IF($E$9="Definir sistema",0,IF($E$9="Lineal",$C$10/5,IF($E$9="Decreciente",C10/$G$6,C14/$G$6))) -> 0.066666667 | F14: =D14*E14 -> 324533.33 | G14: =D5-F10-F11-F12-F13-F14 -> 912000 | M14: =K14*I14 -> 0 | N14: =L14*I14 -> 0
D15: Valor Amortizable | E15: =SUM(E10:E14) -> 1 | F15: =SUM(F10:F14) -> 4868000 | G15: =+G14-D6 -> 2.3283064e-10 | M15: =K15*I15 -> 0 | N15: =L15*I15 -> 0
M16: =SUM(M6:M15) -> 5780000 | N16: =SUM(N6:N15) -> 912000

Sheet Amortización Edificio
C3: Amortización Edificio
C5: Valor inicial | F5: Vida Util : 33 Años
C6: Valor Final | D6: =+D5-D7 -> 0 | F6: Suma Cuotas | G6: =(COUNT(C10:C42)*(COUNT(C10:C42)+1))/2 -> 561
C7: Valor amortizable
C9: Cuota Número | D9: Valor Amortizable | E9: Amortización | F9: Valor Cuota | G9: Valor Residual por Cuota
C10: 1 | D10: =+$D$7 | E10: =C10/$G$6 -> 0.0017825312 | F10: =D10*E10 -> 0 | G10: =D5-F10 -> 0
C11: =C10+1 -> 2 | D11: =+$D$7 | E11: =C11/$G$6 -> 0.0035650624 | F11: =D11*E11 -> 0 | G11: =G10-F11 -> 0
C12: =C11+1 -> 3 | D12: =+$D$7 | E12: =C12/$G$6 -> 0.0053475936 | F12: =D12*E12 -> 0 | G12: =G11-F12 -> 0
C13: =C12+1 -> 4 | D13: =+$D$7 | E13: =C13/$G$6 -> 0.0071301248 | F13: =D13*E13 -> 0 | G13: =G12-F13 -> 0
C14: =C13+1 -> 5 | D14: =+$D$7 | E14: =C14/$G$6 -> 0.008912656 | F14: =D14*E14 -> 0 | G14: =G13-F14 -> 0
C15: =C14+1 -> 6 | D15: =+$D$7 | E15: =C15/$G$6 -> 0.010695187 | F15: =D15*E15 -> 0 | G15: =G14-F15 -> 0
C16: =C15+1 -> 7 | D16: =+$D$7 | E16: =C16/$G$6 -> 0.012477718 | F16: =D16*E16 -> 0 | G16: =G15-F16 -> 0
C17: =C16+1 -> 8 | D17: =+$D$7 | E17: =C17/$G$6 -> 0.01426025 | F17: =D17*E17 -> 0 | G17: =G16-F17 -> 0
C18: =C17+1 -> 9 | D18: =+$D$7 | E18: =C18/$G$6 -> 0.016042781 | F18: =D18*E18 -> 0 | G18: =G17-F18 -> 0
C19: =C18+1 -> 10 | D19: =+$D$7 | E19: =C19/$G$6 -> 0.017825312 | F19: =D19*E19 -> 0 | G19: =G18-F19 -> 0
C20: =C19+1 -> 11 | D20: =+$D$7 | E20: =C20/$G$6 -> 0.019607843 | F20: =D20*E20 -> 0 | G20: =G19-F20 -> 0
C21: =C20+1 -> 12 | D21: =+$D$7 | E21: =C21/$G$6 -> 0.021390374 | F21: =D21*E21 -> 0 | G21: =G20-F21 -> 0
C22: =C21+1 -> 13 | D22: =+$D$7 | E22: =C22/$G$6 -> 0.023172906 | F22: =D22*E22 -> 0 | G22: =G21-F22 -> 0
... C42: =C41+1 -> 33 | D42: =+$D$7 | E42: =C42/$G$6 -> 0.058823529 | F42: =D42*E42 -> 0 | G42: =G41-F42 -> 0
D43: Valor Amortizable | E43: =SUM(E10:E42) -> 1 | F43: =SUM(F10:F42) -> 0 | G43: =+G42-D6 -> 0

Sheet Amortización Rodados
C3: Amortización Rodados | I3: Detalle de los rodados
C5: Valor inicial | D5: =M16 -> 0 | F5: Vida Util : 5 Años | I5: Cantidad | J5: Tipo de rodado | K5: Valor unitario incial | L5: Valor unitario final | M5: Valor inicial Total | N5: Valor final Total
C6: Valor Final | D6: =N16 -> 0 | F6: Suma Cuotas | G6: =(COUNT(C10:C14)*(COUNT(C10:C14)+1))/2 -> 15 | L6: =0.2*K6 -> 0 | M6: =K6*I6 -> 0 | N6: =L6*I6 -> 0
C7: Valor amortizable | D7: =+D5-D6 -> 0 | M7: =K7*I7 -> 0 | N7: =L7*I7 -> 0 | P7: Creciente
M8: =K8*I8 -> 0 | N8: =L8*I8 -> 0 | P8: Decreciente
C9: Cuota Número | D9: Valor Amortizable | E9: Creciente | F9: Valor Cuota | G9: Valor Residual por Cuota | M9: =K9*I9 -> 0 | N9: =L9*I9 -> 0 | P9: Lineal
C10: 1 | D10: =$D$7 -> 0 | E10: =IF($E$9="Definir sistema",0,IF($E$9="Lineal",$C$10/5,IF($E$9="Decreciente",C14/$G$6,C10/$G$6))) -> 0.066666667 | F10: =D10*E10 -> 0 | G10: =D5-F10 -> 0 | M10: =K10*I10 -> 0 | N10: =L10*I10 -> 0 | P10: Definir Sistema
C11: =C10+1 -> 2 | D11: =+D10 -> 0 | E11: =IF($E$9="Definir sistema",0,IF($E$9="Lineal",$C$10/5,IF($E$9="Decreciente",C13/$G$6,C11/$G$6))) -> 0.13333333 | F11: =D11*E11 -> 0 | G11: =D5-F10-F11 -> 0 | M11: =K11*I11 -> 0 | N11: =L11*I11 -> 0
C12: =C11+1 -> 3 | D12: =+D11 -> 0 | E12: =IF($E$9="Definir sistema",0,IF($E$9="Lineal",$C$10/5,IF($E$9="Decreciente",C12/$G$6,C12/$G$6))) -> 0.2 | F12: =D12*E12 -> 0 | G12: =D5-F10-F11-F12 -> 0 | M12: =K12*I12 -> 0 | N12: =L12*I12 -> 0
C13: =C12+1 -> 4 | D13: =+D12 -> 0 | E13: =IF($E$9="Definir sistema",0,IF($E$9="Lineal",$C$10/5,IF($E$9="Decreciente",C11/$G$6,C13/$G$6))) -> 0.26666667 | F13: =D13*E13 -> 0 | G13: =D5-F10-F11-F12-F13 -> 0 | M13: =K13*I13 -> 0 | N13: =L13*I13 -> 0
C14: =C13+1 -> 5 | D14: =+D13 -> 0 | E14: =IF($E$9="Definir sistema",0,IF($E$9="Lineal",$C$10/5,IF($E$9="Decreciente",C10/$G$6,C14/$G$6))) -> 0.33333333 | F14: =D14*E14 -> 0 | G14: =D5-F10-F11-F12-F13-F14 -> 0 | M14: =K14*I14 -> 0 | N14: =L14*I14 -> 0
D15: Valor Amortizable | E15: =SUM(E10:E14) -> 1 | F15: =SUM(F10:F14) -> 0 | G15: =+G14-D6 -> 0 | M15: =K15*I15 -> 0 | N15: =L15*I15 -> 0
M16: =SUM(M6:M15) -> 0 | N16: =SUM(N6:N15) -> 0

Sheet Amortización Desarrollos
C3: Amortización Desarrollos | I3: Detalle desarrollos de Software
C5: Valor inicial | D5: =M16 -> 10130000 | F5: Vida Util : 3 Años | I5: Cantidad | J5: Tipo de mueble | K5: Valor unitario incial | L5: Valor unitario final | M5: Valor inicial Total | N5: Valor final Total
C6: Valor Final | D6: =N16 -> 0.00101 | F6: Suma Cuotas | G6: =(COUNT(C10:C12)*(COUNT(C10:C12)+1))/2 -> 6 | I6: 100 | J6: esp32 para simulacion de firmware de termo | K6: =20*1500*1.21 -> 36300 | L6: 1e-05 | M6: =K6*I6 -> 3630000 | N6: =L6*I6 -> 0.001
C7: Valor amortizable | D7: =+D5-D6 -> 10130000 | I7: 1 | J7: Desarrollo de Firmware/Código del Termo | K7: 6500000 | L7: 1e-05 | M7: =K7*I7 -> 6500000 | N7: =L7*I7 -> 1e-05 | P7: Creciente
I8: 0 | J8: Licencias de programas de modelado | L8: 1e-05 | M8: =K8*I8 -> 0 | N8: =L8*I8 -> 0 | P8: Decreciente
C9: Cuota Número | D9: Valor Amortizable | E9: Decreciente | F9: Valor Cuota | G9: Valor Residual por Cuota | M9: =K9*I9 -> 0 | N9: =L9*I9 -> 0 | P9: Lineal
C10: 1 | D10: =$D$7 -> 10130000 | E10: =IF($E$9="Definir sistema",0,IF($E$9="Lineal",$C$10/3,IF($E$9="Decreciente",C12/$G$6,C10/$G$6))) -> 0.5 | F10: =D10*E10 -> 5065000 | G10: =+D5-F10 -> 5065000 | M10: =K10*I10 -> 0 | N10: =L10*I10 -> 0 | P10: Definir Sistema
C11: 2 | D11: =$D$7 -> 10130000 | E11: =IF($E$9="Definir sistema",0,IF($E$9="Lineal",$C$10/3,IF($E$9="Decreciente",C11/$G$6,C11/$G$6))) -> 0.33333333 | F11: =D11*E11 -> 3376666.7 | G11: =+G10-F11 -> 1688333.3 | M11: =K11*I11 -> 0 | N11: =L11*I11 -> 0
C12: 3 | D12: =$D$7 -> 10130000 | E12: =IF($E$9="Definir sistema",0,IF($E$9="Lineal",$C$10/3,IF($E$9="Decreciente",C10/$G$6,C12/$G$6))) -> 0.16666667 | F12: =D12*E12 -> 1688333.3 | G12: =+G11-F12 -> 0.0010100012 | M12: =K12*I12 -> 0 | N12: =L12*I12 -> 0
D13: Valor Amortizable | E13: =SUM(E10:E12) -> 1 | F13: =SUM(F10:F12) -> 10130000 | G13: =+G12-D6 -> 1.1713803e-09 | M13: =K13*I13 -> 0 | N13: =L13*I13 -> 0
M14: =K14*I14 -> 0 | N14: =L14*I14 -> 0
M15: =K15*I15 -> 0 | N15: =L15*I15 -> 0
M16: =SUM(M6:M15) -> 10130000 | N16: =SUM(N6:N15) -> 0.00101

Sheet Amortización Informática
A1: =K7*0.2 -> 40000
C3: Amortización Informática | I3: Detalle de los equipos informáticos
C5: Valor inicial | D5: =M16 -> 25980000 | F5: Vida Util : 5 Años | I5: Cantidad | J5: Tipo de mueble | K5: Valor unitario incial | L5: Valor unitario final | M5: Valor inicial Total | N5: Valor final Total
C6: Valor Final | D6: =N16 -> 5000000 | F6: Suma Cuotas | G6: =(COUNT(C10:C14)*(COUNT(C10:C14)+1))/2 -> 15 | I6: 10 | J6: Notebook Gama Media i7 | K6: 1000000 | L6: 200000 | M6: =K6*I6 -> 10000000 | N6: =L6*I6 -> 2000000
C7: Valor amortizable | D7: =+D5-D6 -> 20980000 | I7: 3 | J7: Impresora láser Epson | K7: 200000 | L7: 20000 | M7: =K7*I7 -> 600000 | N7: =L7*I7 -> 60000 | P7: Creciente
I8: 3 | J8: Samsung A50 | K8: 400000 | L8: 80000 | M8: =K8*I8 -> 1200000 | N8: =L8*I8 -> 240000 | P8: Decreciente
C9: Cuota Número | D9: Valor Amortizable | E9: Decreciente | F9: Valor Cuota | G9: Valor Residual por Cuota | I9: 5 | J9: PCs de Escritorio para Ingeniería para simulaciones | K9: 2500000 | L9: 500000 | M9: =K9*I9 -> 12500000 | N9: =L9*I9 -> 2500000 | P9: Lineal
C10: 1 | D10: =$D$7 -> 20980000 | E10: =5/15 -> 0.33333333 | F10: =D10*E10 -> 6993333.3 | G10: =+D5-F10 -> 18986667 | I10: 2 | J10: placas de video nvidia para Software de simulacion | K10: =1400*600 -> 840000 | L10: 100000 | M10: =K10*I10 -> 1680000 | N10: =L10*I10 -> 200000 | P10: Definir Sistema
C11: 2 | D11: =$D$7 -> 20980000 | E11: =4/15 -> 0.26666667 | F11: =D11*E11 -> 5594666.7 | G11: =+G10-F11 -> 13392000 | M11: =K11*I11 -> 0 | N11: =L11*I11 -> 0
C12: 3 | D12: =$D$7 -> 20980000 | E12: =3/15 -> 0.2 | F12: =D12*E12 -> 4196000 | G12: =+G11-F12 -> 9196000 | M12: =K12*I12 -> 0 | N12: =L12*I12 -> 0
C13: 4 | D13: =$D$7 -> 20980000 | E13: =2/15 -> 0.13333333 | F13: =D13*E13 -> 2797333.3 | G13: =+G12-F13 -> 6398666.7 | M13: =K13*I13 -> 0 | N13: =L13*I13 -> 0
C14: 5 | D14: =$D$7 -> 20980000 | E14: =1/15 -> 0.066666667 | F14: =D14*E14 -> 1398666.7 | G14: =+G13-F14 -> 5000000 | M14: =K14*I14 -> 0 | N14: =L14*I14 -> 0
D15: Valor Amortizable | E15: =SUM(E10:E14) -> 1 | F15: =SUM(F10:F14) -> 20980000 | G15: =+G14-D6 -> -9.3132257e-10 | M15: =K15*I15 -> 0 | N15: =L15*I15 -> 0
M16: =SUM(M6:M15) -> 25980000 | N16: =SUM(N6:N15) -> 5000000

Sheet Amortización Máquinas, Herram i
C3: Amortización Máquinas | I3: Detalle de las máquinarias, herramientas, instrumental
C5: Valor inicial | D5: =M16 -> 5760000 | F5: Vida Util : 5 Años | I5: Cantidad | J5: Tipo de mueble | K5: Valor unitario incial | L5: Valor unitario final | M5: Valor inicial Total | N5: Valor final Total
C6: Valor Final | D6: =N16 -> 2316000 | F6: Suma Cuotas | G6: =(COUNT(C10:C14)*(COUNT(C10:C14)+1))/2 -> 15 | I6: 1 | J6: Horno de curado eléctrico industrial | K6: 2400000 | L6: 1200000 | M6: =K6*I6 -> 2400000 | N6: =L6*I6 -> 1200000 | S6: Creciente
C7: Valor amortizable | D7: =+D5-D6 -> 3444000 | I7: 1 | J7: Equipo de pintura electrostática | K7: 1100000 | L7: 550000 | M7: =K7*I7 -> 1100000 | N7: =L7*I7 -> 550000 | S7: Decreciente
I8: 1 | J8: Compresor de aire industrial 50L | K8: 450000 | L8: 225000 | M8: =K8*I8 -> 450000 | N8: =L8*I8 -> 225000 | S8: Lineal
C9: Cuota Número | D9: Valor Amortizable | E9: Creciente | F9: Valor Cuota | G9: Valor Residual por Cuota | I9: 1 | J9: Banco de prueba de estanqueidad | K9: 400000 | L9: 200000 | M9: =K9*I9 -> 400000 | N9: =L9*I9 -> 200000 | S9: DEFINIR SISTEMA
C10: 1 | D10: =$D$7 -> 3444000 | E10: =IF($E$9="Definir sistema",0,IF($E$9="Lineal",$C$10/5,IF($E$9="Decreciente",C14/$G$6,C10/$G$6))) -> 0.066666667 | F10: =D10*E10 -> 229600 | G10: =D5-F10 -> 5530400 | I10: 2 | J10: Estaciones de soldado profesional SMD | K10: 290000 | L10: 29000 | M10: =K10*I10 -> 580000 | N10: =L10*I10 -> 58000
C11: 2 | D11: =$D$7 -> 3444000 | E11: =IF($E$9="Definir sistema",0,IF($E$9="Lineal",$C$10/5,IF($E$9="Decreciente",C13/$G$6,C11/$G$6))) -> 0.13333333 | F11: =D11*E11 -> 459200 | G11: =G10-F11 -> 5071200 | I11: 1 | J11: Multímetro digital automático de banco | K11: 180000 | L11: 18000 | M11: =K11*I11 -> 180000 | N11: =L11*I11 -> 18000
C12: 3 | D12: =$D$7 -> 3444000 | E12: =IF($E$9="Definir sistema",0,IF($E$9="Lineal",$C$10/5,IF($E$9="Decreciente",C12/$G$6,C12/$G$6))) -> 0.2 | F12: =D12*E12 -> 688800 | G12: =G11-F12 -> 4382400 | I12: 1 | J12: Cámara termográfica para control NTC | K12: 650000 | L12: 65000 | M12: =K12*I12 -> 650000 | N12: =L12*I12 -> 65000
C13: 4 | D13: =$D$7 -> 3444000 | E13: =IF($E$9="Definir sistema",0,IF($E$9="Lineal",$C$10/5,IF($E$9="Decreciente",C11/$G$6,C13/$G$6))) -> 0.26666667 | F13: =D13*E13 -> 918400 | G13: =G12-F13 -> 3464000 | M13: =K13*I13 -> 0 | N13: =L13*I13 -> 0
C14: 5 | D14: =$D$7 -> 3444000 | E14: =IF($E$9="Definir sistema",0,IF($E$9="Lineal",$C$10/5,IF($E$9="Decreciente",C10/$G$6,C14/$G$6))) -> 0.33333333 | F14: =D14*E14 -> 1148000 | G14: =G13-F14 -> 2316000 | M14: =K14*I14 -> 0 | N14: =L14*I14 -> 0
D15: Valor Amortizable | E15: =SUM(E10:E14) -> 1 | F15: =SUM(F10:F14) -> 3444000 | G15: =+G14-D6 -> 0 | M15: =K15*I15 -> 0 | N15: =L15*I15 -> 0
M16: =SUM(M6:M15) -> 5760000 | N16: =SUM(N6:N15) -> 2316000

Sheet Costos Variables de Fabricación
C3: Costo Variables Fabricación
C5: Mano de Obra Directa | I5: Materia Prima (Unidad de medida de compra)
C6: Puesto | D6: Sueldo Mesual Bruto | E6: Cantidad de personal | F6: Total | I6: Detalle Materia Prima | J6: Precio | K6: Unidad de medida
C7: Operario de ensamblado | D7: 822402.24 | E7: 1 | F7: =D7*E7 -> 822402.24 | I7: Cuerpo Acero Inox 18/8 (Doble capa) | J7: 5500 | K7: Unidad
C8: Operarios de estación de soldado (electrónica) | D8: 902156.64 | E8: 1 | F8: =D8*E8 -> 902156.64 | I8: Placa electrónica PCB USB-C + Sensores | J8: 6800 | K8: Unidad
F9: =D9*E9 -> 0 | I9: Resistencia calefactora (Thin-Film) | J9: 3500 | K9: Unidad
F10: =D10*E10 -> 0 | I10: Tapón cebador polímero + Juntas | J10: 1500 | K10: Unidad
F11: =D11*E11 -> 0 | I11: Packaging premium alto impacto | J11: 1000 | K11: Unidad
F12: =D12*E12 -> 0 | I12: Cable USB-C de Alta Performance (5A / 100W) | J12: 1800 | K12: Unidad
F13: =D13*E13 -> 0 | I13: Módulo BMS / Regulador de potencia | J13: 1500 | K13: Unidad
F14: =D14*E14 -> 0 | I14: Pintura electrostática y consumibles | J14: 1000 | K14: Unidad
F15: =D15*E15 -> 0 | I15: Pack Celdas de Litio de Alta Descarga (3x 21700) | J15: 4800 | K15: Unidad
C16: Total Mensual | E16: =SUM(E7:E15) -> 2 | F16: =SUM(F7:F15) -> 1724558.9
C17: Total Sueldo Fabril Anual | F17: =12*F16 -> 20694707
I18: Materia Prima por Producto | J18: Consumo x unidad | K18: Precio | L18: Costo
C19: Total Aguinaldo Anual | F19: =F16 -> 1724558.9 | I19: =IF(I7="","",I7) -> Cuerpo Acero Inox 18/8 (Doble capa) | J19: 1 | K19: =+J7 -> 5500 | L19: =J19*K19 -> 5500
I20: =IF(I8="","",I8) -> Placa electrónica PCB USB-C + Sensores | J20: 1 | K20: =+J8 -> 6800 | L20: =J20*K20 -> 6800
C21: Total de cargas sociales del empleador | F21: =Consideraciones!$D$18*(F17+F19) -> 13451559 | I21: =IF(I9="","",I9) -> Resistencia calefactora (Thin-Film) | J21: 1 | K21: =+J9 -> 3500 | L21: =J21*K21 -> 3500
I22: =IF(I10="","",I10) -> Tapón cebador polímero + Juntas | J22: 1 | K22: =+J10 -> 1500 | L22: =J22*K22 -> 1500
I23: =IF(I11="","",I11) -> Packaging premium alto impacto | J23: 1 | K23: =+J11 -> 1000 | L23: =J23*K23 -> 1000
I24: Cable USB-C de Alta Performance (5A / 100W) | J24: 1 | K24: =+J12 -> 1800 | L24: =J24*K24 -> 1800
I25: Módulo BMS / Regulador de potencia | J25: 1 | K25: =+J13 -> 1500 | L25: =J25*K25 -> 1500
I26: Pintura electrostática y consumibles | J26: 1 | K26: =+J14 -> 1000 | L26: =J26*K26 -> 1000
C27: Calculo de Viaticos y refrigerio: | I27: Pack Celdas de Litio de Alta Descarga (3x 21700) | J27: 1 | K27: =+J15 -> 4800 | L27: =J27*K27 -> 4800
C28: Costo Viatico y refrigerio x persona y por día | F28: 5704.17
C29: Personas | F29: 2 | G29: Operarios | I29: Costo unitario Materia Prima | L29: =SUM(L19:L27) -> 27400 | M29: $ /Unidad
C30: Dias por mes | F30: 22 | G30: Días / Mes | I30: Producción Terminada | L30: =Mercado!H27 -> 4000 | M30: Unidades
C31: Meses por año | F31: =+Consideraciones!D10 -> 12 | G31: Meses / Año | I31: Costo Total Materia Prima | L31: =+L30*L29 -> 109600000
C32: Total Anual Viaticos y refrigerios | F32: =+F28*F29*F30*F31 -> 3011801.8
I33: Costo Variable Total de Fabricación | L33: =+L31+F34 -> 1.4848263e+08
C34: COSTO TOTAL MANO DE OBRA DIRECTA | F34: =+F32+F21+F19+F17 -> 38882626 | I34: Costo Variable Unitario de Fabricación | L34: =+L29+F35 -> 37120.657 | M34: $ /Unidad
C35: COSTO UNITARIO MANO DE OBRA DIRECTA | F35: =F34/Mercado!H27 -> 9720.6566 | G35: $ / Unidad | I35: Incidencia del costo sobre el precio de venta | L35: =+L34/Mercado!F23 -> 0.23128135

Sheet Gastos Fijos de Fabricación
C3: Costo Fijos Fabricación
C5: Mano de Obra Indirecta | H5: Consumo Energetico fabril
C6: Puesto | D6: Sueldo Mesual Bruto | E6: Cantidad de personal | F6: Total | H6: Horas laborables diarias | I6: =+Consideraciones!D12 -> 8 | K6: Tipo de energia utilizada | L6: Electricidad
C7: Supervisor de Planta | D7: 1150000 | E7: 1 | F7: =D7*E7 -> 1150000 | P7: Gas
H8: Cantidad de máquinas eléctricas | I8: 14 | P8: Electricidad
H9: Cantidad de máquinas a Gas | I9: 0 | P9: Ambos
C10: Total Mensual | E10: =SUM(E7:E9) -> 1 | F10: =SUM(F7:F9) -> 1150000 | P10: Ninguno
C11: Total Sueldo Fabril Anual | F11: =12*F10 -> 13800000 | H11: $ (KW HORA x Maquina) | I11: =+IF(OR($L$6="Electricidad",$L$6="Ambos"),0.4,"") -> 0.4 | K11: Consumo KW x hora x Maquina | L11: 1.1
H12: $ (M3 HORA x Maquina) | I12: =+IF(OR($L$6="Gas",$L$6="Ambos"),0.2,"") | K12: Consumo M3 x hora x Máquina | L12: 2.3
C14: Total Aguinaldo Anual | F14: =F10 -> 1150000 | H14: Consumo total energía eléctrica (anual) | L14: =IF($I$11="",0,I8*I11*L11*Consideraciones!D12*Consideraciones!D8) -> 1034.88
H15: Consumo total gas (anual) | L15: =IF(I12="",0,I9*I12*L12*Consideraciones!$D$12*Consideraciones!$D$8) -> 0
C17: Total de cargas sociales del empleador | F17: =Consideraciones!D18*(F14+F11) -> 8970000 | H17: Consumo de Energia Total Anual: | L17: =IF(L6="Ninguno",0,(L14+L15)*Consideraciones!D10) -> 12418.56
C19: Calculo de Viaticos y refrigerio: | H19: Otros Gastos de Fabricación
C20: Costo Viatico y refrigerio x persona y por día | F20: 0 | H20: Detalle | L20: Costo
C21: Personas | F21: 0 | H21: Licencias office 365 | L21: 600000 | M21: $ / Año
C22: Dias por mes | F22: =Consideraciones!D8 -> 21 | M22: $ / Año
C23: Meses por año | F23: =+Consideraciones!D10 -> 12 | M23: $ / Año
C24: Total Anual Viaticos y refrigerios | F24: =+F20*F21*F22*F23 -> 0 | M24: $ / Año
C25: Costo Total Mano de Obra indirecta | F25: =+F24+F17+F14+F11 -> 23920000 | H25: Alquiler de la planta | L25: 48720000 | M25: ANUAL
H26: Otros Gastos de Fabricación | L26: =SUM(L21:L25) -> 49320000
H28: Gastos Fabricación Fijos | L28: =+L26+L17+F25 -> 73252419

Sheet Gastos de Comercialización
C3: Gastos Comercialización
C5: Gastos Comercialización Fijos | H5: Gastos Comercialización Variables
C6: Puesto | D6: Sueldo Mensual Bruto | E6: Cantidad de personal | F6: Total | J6: Local | K6: =+IF($E$7="","",0.4%) -> 0.004
C7: Coordinador de Growth Marketing y ventas B2B | D7: 1200000 | E7: 1 | F7: =E7*D7 -> 1200000 | J7: Viajante | K7: =+IF($E$7="","",0.8%) -> 0.008 | L7: Gastos Comerciales
E8: 1
H9: Año 1 | I9: 0.04 | J9: Ingresos Brutos | K9: Comisión Vendedor | L9: Variables Unitarios
C10: Total Mensual | F10: =SUM(F7:F9) -> 1200000 | H10: Precio al publico | I10: =+Mercado!E23 -> 165000 | J10: =+I10*$I$9 -> 6600 | K10: =IF($E$7="","",$K$6*I10) -> 660 | L10: =IF($K$6="",J10,+K10+J10) -> 7260
C11: Total Sueldo Comercial Anual | F11: =F10*12 -> 14400000 | H11: Precio x mayor | I11: =+Mercado!D23 -> 150000 | J11: =+$I$9*I11 -> 6000 | K11: =IF($E$7="","",$K$7*I11) -> 1200 | L11: =IF($K$7="",J11,+K11+J11) -> 7200
H12: Precio Promedio Ponderado (PPP) | I12: =+Mercado!F23 -> 160500 | L12: =+Mercado!$J$6*L10+Mercado!$I$6*L11 -> 7242
C13: Total Aguinaldo Anual | F13: =F10 -> 1200000 | L13: =+L12/I12 -> 0.045121495
H14: Año 2
C15: Total de cargas sociales del empleador | F15: =Consideraciones!D18*(F13+F11) -> 9360000 | H15: Precio al publico | I15: =+Mercado!E24 -> 165000 | J15: =+I15*$I$9 -> 6600 | K15: =IF($E$7="","",$K$6*I15) -> 660 | L15: =IF($K$6="",J15,+K15+J15) -> 7260
H16: Precio x mayor | I16: =+Mercado!D24 -> 150000 | J16: =+$I$9*I16 -> 6000 | K16: =IF($E$7="","",$K$7*I16) -> 1200 | L16: =IF($K$7="",J16,+K16+J16) -> 7200
C17: Calculo de Viaticos y refrigerio: | H17: Precio Promedio Ponderado (PPP) | I17: =+Mercado!F24 -> 160500 | L17: =+Mercado!$J$6*L15+Mercado!$I$6*L16 -> 7242
C18: Costo Viatico y refrigerio x persona y día | F18: 0 | L18: =+L17/I17 -> 0.045121495
C19: Días por mes | F19: =+Consideraciones!D9 -> 21 | H19: Año 3
C20: Meses por año | F20: =+Consideraciones!D10 -> 12 | H20: Precio al publico | I20: =+Mercado!E25 -> 165000 | J20: =+I20*$I$9 -> 6600 | K20: =IF($E$7="","",$K$6*I20) -> 660 | L20: =IF($K$6="",J20,+K20+J20) -> 7260
C21: Total Anual Viatico y refrigerios | F21: =+F20*F19*F18*E7 -> 0 | H21: Precio x mayor | I21: =+Mercado!D25 -> 150000 | J21: =+$I$9*I21 -> 6000 | K21: =IF($E$7="","",$K$7*I21) -> 1200 | L21: =IF($K$7="",J21,+K21+J21) -> 7200
H22: Precio Promedio Ponderado (PPP) | I22: =+Mercado!F25 -> 160500 | L22: =+Mercado!$J$6*L20+Mercado!$I$6*L21 -> 7242
C23: Total Sueldo comercial | F23: =F21+F15+F13+F11 -> 24960000 | L23: =+L22/I22 -> 0.045121495
H24: Año 4
C25: Consumo energetico area comercial | H25: Precio al publico | I25: =+Mercado!E26 -> 165000 | J25: =+I25*$I$9 -> 6600 | K25: =IF($E$7="","",$K$6*I25) -> 660 | L25: =IF($K$6="",J25,+K25+J25) -> 7260
C26: Horas laborables diarias | D26: 8 | H26: Precio x mayor | I26: =+Mercado!D26 -> 150000 | J26: =+$I$9*I26 -> 6000 | K26: =IF($E$7="","",$K$7*I26) -> 1200 | L26: =IF($K$7="",J26,+K26+J26) -> 7200
C27: Cantidad de locales comerciales | D27: KW por local | E27: Costo KWHR | F27: Total | H27: Precio Promedio Ponderado (PPP) | I27: =+Mercado!F26 -> 160500 | L27: =+Mercado!$J$6*L25+Mercado!$I$6*L26 -> 7242
C28: 1 | D28: 5 | E28: 8.9 | F28: =C28*D28*E28*Consideraciones!D9*Consideraciones!D13*Consideraciones!D10 -> 89712 | L28: =+L27/I27 -> 0.045121495
C29: Consumo de Energia Total Anual: | F29: =F28 -> 89712 | H29: Año 5
H30: Precio al publico | I30: =+Mercado!E27 -> 165000 | J30: =+I30*$I$9 -> 6600 | K30: =IF($E$7="","",$K$6*I30) -> 660 | L30: =IF($K$6="",J30,+K30+J30) -> 7260
C31: Puesto | D31: Sueldo Mensual | E31: Cantidad de personal | F31: Total | H31: Precio x mayor | I31: =+Mercado!D27 -> 150000 | J31: =+$I$9*I31 -> 6000 | K31: =IF($E$7="","",$K$7*I31) -> 1200 | L31: =IF($K$7="",J31,+K31+J31) -> 7200
C32: N/A | D32: 0 | E32: 0 | F32: =E32*D32 -> 0 | H32: Precio Promedio Ponderado (PPP) | I32: =+Mercado!F27 -> 160500 | L32: =+Mercado!$J$6*L30+Mercado!$I$6*L31 -> 7242
C33: Total Sueldo Transporte | F33: =F32*12 -> 0 | L33: =+L32/I32 -> 0.045121495
C35: Total Aguinaldo Anual | F35: =F32 -> 0 | H35: Otros Gastos Comerciales
H36: Detalle | K36: Costo
C37: Total de cargas sociales del empleador | F37: =Consideraciones!D18*(F35+F33) -> 0
H38: Inversión Fija en Branding y Contenido | K38: =300000*12 -> 3600000
C39: Calculo de Viaticos y refrigerio: | H39: Alquiler y Mantenimiento del Área de Almacenamiento | K39: =400000*12 -> 4800000
C40: Costo Viatico y refrigerio x persona y día | F40: 0
C41: Días por mes | F41: =+Consideraciones!D9 -> 21 | H41: Otros Gastos Comerciales | K41: =SUM(K37:K40) -> 8400000
C42: Meses por año | F42: =+Consideraciones!D10 -> 12
C43: Total Anual Viatico y refrigerios | F43: =+F42*F41*F40*E32 -> 0
H44: Gastos Comercialización Fijos | K44: =K41+F47+F29+F23 -> 33449712
...

Sheet Gastos Adm y Finanzas
C3: Gastos Administrativos Fijos
D5: Sueldo Mesual Bruto | E5: Cantidad de personal | F5: Total
C6: Administrador General / Socio Administrador | D6: 1300000 | E6: 1 | F6: =E6*D6 -> 1300000
D7: 0 | E7: 0 | F7: =E7*D7 -> 0
D8: 0 | E8: 0 | F8: =E8*D8 -> 0
F9: =E9*D9 -> 0
F11: =E11*D11 -> 0
C12: Total Mensual | E12: =SUM(E6:E11) -> 1 | F12: =SUM(F6:F11) -> 1300000
C13: Total Sueldo Adm. Anual | F13: =F12*12 -> 15600000
C15: Total Aguinaldo Anual | F15: =F12 -> 1300000
C17: Total de cargas sociales del empleador | F17: =Consideraciones!D18*(F15+F13) -> 10140000
C19: Calculo de Viaticos y refrigerio:
C20: Costo Viatico y refrigerio x persona y día | F20: 0
C21: Días por mes | F21: =+Consideraciones!D9 -> 21
C22: Meses por año | F22: =+Consideraciones!D10 -> 12
C23: Total Anual Viatico y refrigerios | F23: =+F22*F21*F20*E12 -> 0
C25: Total Sueldo administrativo | F25: =F23+F17+F15+F13 -> 27040000
C27: Otros gastos administrativos | F27: 445000
C29: Gastos Administrativos Fijos | F29: =+F27+F25 -> 27485000

Sheet Activo no Corriente
C3: Activo no Corriente o Activo Fijo
C5: Valores Inciales y Residuales
E7: Año 0 | F7: Año 1 | G7: Año 2 | H7: Año 3 | I7: Año 4 | J7: Año 5
D8: Edificio | E8: =+'Amortización Edificio'!D5 | F8: =+'Amortización Edificio'!G10 -> 0 | G8: =+'Amortización Edificio'!G11 -> 0 | H8: =+'Amortización Edificio'!G12 -> 0 | I8: =+'Amortización Edificio'!G13 -> 0 | J8: =+'Amortización Edificio'!G14 -> 0
D9: Muebles y utiles | E9: =+'Amortización Muebles y Utiles'!D5 -> 5780000 | F9: =+'Amortización Muebles y Utiles'!G10 -> 4157333.3 | G9: =+'Amortización Muebles y Utiles'!G11 -> 2859200 | H9: =+'Amortización Muebles y Utiles'!G12 -> 1885600 | I9: =+'Amortización Muebles y Utiles'!G13 -> 1236533.3 | J9: =+'Amortización Muebles y Utiles'!G14 -> 912000
D10: Rodados | E10: =+'Amortización Rodados'!D5 -> 0 | F10: =+'Amortización Rodados'!G10 -> 0 | G10: =+'Amortización Rodados'!G11 -> 0 | H10: =+'Amortización Rodados'!G12 -> 0 | I10: =+'Amortización Rodados'!G13 -> 0 | J10: =+'Amortización Rodados'!G14 -> 0
D11: Informática | E11: =+'Amortización Informática'!D5 -> 25980000 | F11: =+'Amortización Informática'!G10 -> 18986667 | G11: =+'Amortización Informática'!G11 -> 13392000 | H11: =+'Amortización Informática'!G12 -> 9196000 | I11: =+'Amortización Informática'!G13 -> 6398666.7 | J11: =+'Amortización Informática'!G14 -> 5000000
D12: Desarrollo de firmware | E12: ='Amortización Desarrollos'!M16 -> 10130000 | F12: ='Amortización Desarrollos'!G10 -> 5065000 | G12: ='Amortización Desarrollos'!G11 -> 1688333.3 | H12: ='Amortización Desarrollos'!G12 -> 0.0010100012 | I12: 0 | J12: 0
D13: Máquinas | E13: =+'Amortización Máquinas, Herram i'!D5 -> 5760000 | F13: =+'Amortización Máquinas, Herram i'!G10 -> 5530400 | G13: =+'Amortización Máquinas, Herram i'!G11 -> 5071200 | H13: =+'Amortización Máquinas, Herram i'!G12 -> 4382400 | I13: =+'Amortización Máquinas, Herram i'!G13 -> 3464000 | J13: =+'Amortización Máquinas, Herram i'!G14 -> 2316000
D14: Inversión Activo Fijo | E14: =SUM(E8:E13) -> 47650000 | F14: =SUM(F8:F13) -> 33739400 | G14: =SUM(G8:G13) -> 23010733 | H14: =SUM(H8:H13) -> 15464000 | I14: =SUM(I8:I13) -> 11099200 | J14: =SUM(J8:J13) -> 8228000
D15: IVA Crédito Fiscal | E15: =+E14*Consideraciones!D16 -> 10006500
C16: Cuotas
E19: Año 0 | F19: Año 1 | G19: Año 2 | H19: Año 3 | I19: Año 4 | J19: Año 5
D20: Edificio | E20: 0 | F20: =+'Amortización Edificio'!F10 -> 0 | G20: =+'Amortización Edificio'!F11 -> 0 | H20: =+'Amortización Edificio'!F12 -> 0 | I20: =+'Amortización Edificio'!F13 -> 0 | J20: =+'Amortización Edificio'!F14 -> 0
D21: Muebles y utiles | E21: 0 | F21: =+'Amortización Muebles y Utiles'!F10 -> 1622666.7 | G21: =+'Amortización Muebles y Utiles'!F11 -> 1298133.3 | H21: =+'Amortización Muebles y Utiles'!F12 -> 973600 | I21: =+'Amortización Muebles y Utiles'!F13 -> 649066.67 | J21: =+'Amortización Muebles y Utiles'!F14 -> 324533.33
D22: Rodados | E22: 0 | F22: =+'Amortización Rodados'!F10 -> 0 | G22: =+'Amortización Rodados'!F11 -> 0 | H22: =+'Amortización Rodados'!F12 -> 0 | I22: =+'Amortización Rodados'!F13 -> 0 | J22: =+'Amortización Rodados'!F14 -> 0
D23: Informática Desarrollos | E23: 0 | F23: =+'Amortización Informática'!F10+'Amortización Desarrollos'!F10 -> 12058333 | G23: =+'Amortización Informática'!F11+'Amortización Desarrollos'!F11 -> 8971333.3 | H23: =+'Amortización Informática'!F12+'Amortización Desarrollos'!F12 -> 5884333.3 | I23: =+'Amortización Informática'!F13 -> 2797333.3 | J23: 624000
D24: Máquinas | E24: 0 | F24: =+'Amortización Máquinas, Herram i'!F10 -> 229600 | G24: =+'Amortización Máquinas, Herram i'!F11 -> 459200 | H24: =+'Amortización Máquinas, Herram i'!F12 -> 688800 | I24: =+'Amortización Máquinas, Herram i'!F13 -> 918400 | J24: =+'Amortización Máquinas, Herram i'!F14 -> 1148000
D25: AMORTIZACIÓN | E25: 0 | F25: =SUM(F20:F24) -> 13910600 | G25: =SUM(G20:G24) -> 10728667 | H25: =SUM(H20:H24) -> 7546733.3 | I25: =SUM(I20:I24) -> 4364800 | J25: =SUM(J20:J24) -> 2096533.3

Sheet Capital de trabajo
C2: Inversiones en Capital de Trabajo
C4: Disponibilidades mínimas en caja y Bancos | D4: =+('Costos Variables de Fabricación'!F21+'Gastos de Comercialización'!F23+'Gastos Adm y Finanzas'!F17)*3/12 -> 12137890 | E4: Sueldo de tres meses
C5: Stock de Materias primas | D5: =+'Costos Variables de Fabricación'!L31/60*3 -> 5480000 | E5: Materia Prima por 3 meses
C7: Iva Activo de Trabajo | D7: =+D5*21% -> 1150800
C8: Iva Activo Fijo | D8: ='Activo no Corriente'!E15 -> 10006500 | E8: =D8+D7 -> 11157300
C9: Total Activo de Trabajo sin IVA | D9: =+D4+D5 -> 17617890
C12: Activo de Trabajo | D12: Año 0 | E12: Año 1 | F12: Año 2 | G12: Año 3 | H12: Año 4 | I12: Año 5
C13: Disponibilidades mínimas caja y bancos | D13: =+D9 -> 17617890 | E13: =+'Balances Pro Forma'!F30 -> 1836659.6 | F13: =+'Balances Pro Forma'!I30 -> -6852752.4 | G13: =+'Balances Pro Forma'!L30 -> 23469778 | H13: =+'Balances Pro Forma'!O30 -> 88159163 | I13: =+'Balances Pro Forma'!R30 -> 2.0540466e+08
C14: Crédito x ventas | D14: 0 | E14: =+'Balances Pro Forma'!F32 -> 13191781 | F14: =+'Balances Pro Forma'!I32 -> 18468493 | G14: =+'Balances Pro Forma'!L32 -> 26383562 | H14: =+'Balances Pro Forma'!O32 -> 36936986 | I14: =+'Balances Pro Forma'!R32 -> 52767123
C15: Bienes de Cambio | D15: 0 | E15: =+'Balances Pro Forma'!F34 -> 8794520.5 | F15: =+'Balances Pro Forma'!I34 -> 12312329 | G15: =+'Balances Pro Forma'!L34 -> 17589041 | H15: =+'Balances Pro Forma'!O34 -> 24624658 | I15: =+'Balances Pro Forma'!R34 -> 35178082
C16: Activo Corriente | D16: =SUM(D13:D15) -> 17617890 | E16: =SUM(E13:E15) -> 23822961 | F16: =SUM(F13:F15) -> 23928070 | G16: =SUM(G13:G15) -> 67442381 | H16: =SUM(H13:H15) -> 1.4972081e+08 | I16: =SUM(I13:I15) -> 2.9334986e+08
C17: Deudas con proveedores | D17: 0 | E17: =+'Balances Pro Forma'!F45 -> 13191781 | F17: =+'Balances Pro Forma'!I45 -> 18468493 | G17: =+'Balances Pro Forma'!L45 -> 26383562 | H17: =+'Balances Pro Forma'!O45 -> 36936986 | I17: =+'Balances Pro Forma'!R45 -> 52767123
C18: Deudas bancarias corto plazo | D18: 0 | E18: 0 | F18: 0 | G18: 0 | H18: 0 | I18: 0
C19: Deudas Impositivas | D19: 0 | E19: 0 | F19: 0 | G19: 0 | H19: 0 | I19: 0
C20: Pasivo Corriente | D20: =SUM(D17:D19) -> 0 | E20: =SUM(E17:E19) -> 13191781 | F20: =SUM(F17:F19) -> 18468493 | G20: =SUM(G17:G19) -> 26383562 | H20: =SUM(H17:H19) -> 36936986 | I20: =SUM(I17:I19) -> 52767123
C21: Capital de Trabajo | D21: =+D16-D20 -> 17617890 | E21: =+E16-E20 -> 10631180 | F21: =+F16-F20 -> 5459576.4 | G21: =+G16-G20 -> 41058819 | H21: =+H16-H20 -> 1.1278382e+08 | I21: =+I16-I20 -> 2.4058274e+08
C22: Variación | E22: =+E21-D21 -> -6986709.7 | F22: =+F21-E21 -> -5171603.7 | G22: =+G21-F21 -> 35599242 | H22: =+H21-G21 -> 71725002 | I22: =+I21-H21 -> 1.2779892e+08

Sheet Cuadro de Usos y Fuentes
C3: Fuentes y Usos
C5: USOS | D5: Importe | E5: FUENTES | F5: Importe | G5: Ponderación de las fuentes | P5: =+D14 -> 0.35 | Q5: =+F7 -> 45855114 | R5: =+D12*(1-G12)*F6 -> 5166342.8
C6: Activo de Trabajo | D6: ='Capital de trabajo'!D21 -> 17617890 | E6: Préstamo | F6: =G6*D10 -> 30570076 | G6: 0.4 | Q6: =+D10 -> 76425190 | R6: =+Q6 -> 76425190
C7: Activo no Corriente | D7: ='Activo no Corriente'!E14 -> 47650000 | E7: Capital Social | F7: =D10-F6 -> 45855114 | G7: =F7/F10 -> 0.6
C8: Crédito Fiscal | D8: ='Activo no Corriente'!E15+'Capital de trabajo'!D7 -> 11157300
Q9: =+P5*(Q5/Q6)+(R5/R6) -> 0.2776
C10: Total Usos | D10: =+SUM(D6:D8) -> 76425190 | E10: Fuentes | F10: =SUM(F6:F9) -> 76425190 | G10: =G7+G6 -> 1
C12: Tasa Bancaria (Kd) Activa | D12: =Consideraciones!D6 -> 0.26 | F12: Tasa de impuesto a las ganancias | G12: =+Consideraciones!D17 -> 0.35
C14: Tasa de dividendos de los socios (Ke) | D14: =Consideraciones!D7 -> 0.35
C16: CALCULAR LA TASA DE COSTO DE CAPITAL PROMEDIO (WACC)
C18: WACC = | D18: =$D$26 -> 0.2776
C21: CALCULO
E23: Ke= 35% | F23: ="PN= $"& $F$7 -> PN= $45855113,8896
E24: Kd= 26% | F24: ="D= $"& $F$6 -> D= $30570075,9264
E25: T= 35%
C26: Wacc= | D26: =D14*(F7/(F7+F6))+D12*(1-G12)*(F6/(F7+F6)) -> 0.2776

Sheet Puntos de Equilibrio
C4: Datos
D6: COSTO FIJO | E6: =+'Gastos Fijos de Fabricación'!L28+'Gastos de Comercialización'!K44+'Gastos Adm y Finanzas'!F29+'Activo no Corriente'!F25 -> 1.4809773e+08 | G6: COSTO FABRICACIÓN VARIABLE UNITARIO | H6: =+'Costos Variables de Fabricación'!L34 -> 37120.657
D7: COSTO FIJO EROGABLE | E7: =+'Gastos Fijos de Fabricación'!L28+'Gastos de Comercialización'!K44+'Gastos Adm y Finanzas'!F29 -> 1.3418713e+08 | G7: COSTO COMERCIAL VARIABLE UNITARIO | H7: =+'Gastos de Comercialización'!L12 -> 7242
D8: COSTO FIJO NO EROGABLE | E8: =E6-E7 -> 13910600
D9: PRECIO DE VENTA | E9: =+Mercado!F23 -> 160500 | T9: =+E6 -> 1.4809773e+08 | U9: =+T9/T10 -> 1275.1948
T10: =+E9-H6-H7 -> 116137.34
C13: Punto de Equilibrio Económico
T14: =+T9-E7 -> 13910600 | U14: =+T14/T15 -> 119.77715
G15: B: Beneficio | T15: =+T10 -> 116137.34
G16: I:Ingreso
G17: E:Egreso
G18: Pu: Precio unitario de ventas
D19: Punto de equilibrio Economico: | G19: CVu:Costo fabricacion variable + costo comercial variable
D20: =(E6)/(E9-(H6+H7)) -> 1275.1948 | G20: CF: Costo fijo erogable + No erogable
G21: Qo: Cantidad para el punt ode equilibrio
D25: ="Conclusion: si no vendemos como minimo "&INT(D20)&" piezas, no va a ser rentable la operacion de la empresa" -> Conclusion: si no vendemos como minimo 1275 piezas, no va a ser rentable la operacion de la empresa
C26: El punto de equilibrio económico es de 1275 unidades, por lo que deberán venderse como mínimo 1275 termos anuales para cubrir la totalidad de los costos fijos y variables,
D27: sin generar pérdidas ni utilidades. La venta proyectada para el primer año es de 1.000 unidades, por lo que no se alcanzará el equilibrio económico durante dicho período.
D28: A partir del segundo año, con una proyección de 1.400 unidades, se superará el punto de equilibrio, aunque con un margen de seguridad reducido.
C30: Punto de Equilibrio Financiero
G34: B: Beneficio
G35: I:Ingreso
D36: Punto de equilibrio Financiero: | G36: E:Egreso
D37: =E7/(E9-(H6+H7)) -> 1155.4176 | G37: Pu: Precio unitario de ventas
G38: CVu:Costo fabricacion variable + costo comercial variable
G39: CF: Costo fijo erogable
D40: ="Conclusion: si no vendemos como minimo "&INT(D37)&" termos, no tendriamos la liquidez para seguir operando" -> Conclusion: si no vendemos como minimo 1155 termos, no tendriamos la liquidez para seguir operando | G40: Qo: Cantidad para el punt ode equilibrio
C42: El punto de equilibrio financiero es de 1155 unidades, por lo que deberán venderse como mínimo 1155 termos anuales para cubrir los costos que representan salidas efectivas
C43: de fondos. Durante el primer año, la venta proyectada de 1.000 unidades no será suficiente para alcanzar este nivel. A partir del segundo año, las ventas proyectadas
C44: permitirán cubrir los egresos operativos y mantener la liquidez de la empresa.

Sheet Balances Pro Forma
C3: Estado de Resultados Proyectados y Balance Proforma
C5: Estado de Resultados Proyectados
D6: Unidades | E6: $ unitario | F6: Total Año 1 | G6: Unidades | H6: $ unitario | I6: Total Año 2 | J6: Unidades | K6: $ unitario | L6: Total Año 3 | M6: Unidades | N6: $ unitario | O6: Total Año 4 | P6: Unidades | Q6: $ unitario | R6: Total Año 5
C7: Ingresos por ventas | D7: =+Mercado!H23 -> 1000 | E7: =+Mercado!F23 -> 160500 | F7: =D7*E7 -> 160500000 | G7: =+Mercado!H24 -> 1400 | H7: =+Mercado!F24 -> 160500 | I7: =G7*H7 -> 224700000 | J7: =+Mercado!H25 -> 2000 | K7: =+Mercado!F25 -> 160500 | L7: =J7*K7 -> 321000000 | M7: =+Mercado!H26 -> 2800 | N7: =+Mercado!F26 -> 160500 | O7: =M7*N7 -> 449400000 | P7: =+Mercado!H27 -> 4000 | Q7: =+Mercado!F27 -> 160500 | R7: =P7*Q7 -> 642000000
C8: Costo de ventas | D8: =+D7 -> 1000 | E8: =+'Costos Variables de Fabricación'!L35*E7 -> 37120.657 | F8: =-D8*E8 -> -37120657 | G8: =+G7 -> 1400 | H8: =+'Costos Variables de Fabricación'!L35*H7 -> 37120.657 | I8: =-G8*H8 -> -51968919 | J8: =+J7 -> 2000 | K8: =+'Costos Variables de Fabricación'!L35*K7 -> 37120.657 | L8: =-J8*K8 -> -74241313 | M8: =+M7 -> 2800 | N8: =+'Costos Variables de Fabricación'!L35*N7 -> 37120.657 | O8: =-M8*N8 -> -1.0393784e+08 | P8: =+P7 -> 4000 | Q8: =+'Costos Variables de Fabricación'!L35*Q7 -> 37120.657 | R8: =-P8*Q8 -> -1.4848263e+08
C9: Costos variables comercialización | D9: =+D7 -> 1000 | E9: =+'Gastos de Comercialización'!L13*E7 -> 7242 | F9: =-D9*E9 -> -7242000 | G9: =+G7 -> 1400 | H9: =+'Gastos de Comercialización'!L18*H7 -> 7242 | I9: =-G9*H9 -> -10138800 | J9: =+J7 -> 2000 | K9: =+'Gastos de Comercialización'!L23*K7 -> 7242 | L9: =-J9*K9 -> -14484000 | M9: =+M7 -> 2800 | N9: =+'Gastos de Comercialización'!L28*N7 -> 7242 | O9: =-M9*N9 -> -20277600 | P9: =+P7 -> 4000 | Q9: =+'Gastos de Comercialización'!L33*Q7 -> 7242 | R9: =-P9*Q9 -> -28968000
C10: Contribución Marginal | F10: =SUM(F7:F9) -> 1.1613734e+08 | I10: =SUM(I7:I9) -> 1.6259228e+08 | L10: =SUM(L7:L9) -> 2.3227469e+08 | O10: =SUM(O7:O9) -> 3.2518456e+08 | R10: =SUM(R7:R9) -> 4.6454937e+08
C12: Gastos de fabricación (fijos) | F12: =-'Gastos Fijos de Fabricación'!L28 -> -73252419 | I12: =-'Gastos Fijos de Fabricación'!L28 -> -73252419 | L12: =-'Gastos Fijos de Fabricación'!L28 -> -73252419 | O12: =-'Gastos Fijos de Fabricación'!L28 -> -73252419 | R12: =-'Gastos Fijos de Fabricación'!L28 -> -73252419
C13: Gastos de comercialización (fijos) | F13: =-'Gastos de Comercialización'!K44 -> -33449712 | I13: =-'Gastos de Comercialización'!K44 -> -33449712 | L13: =-'Gastos de Comercialización'!K44 -> -33449712 | O13: =-'Gastos de Comercialización'!K44 -> -33449712 | R13: =-'Gastos de Comercialización'!K44 -> -33449712
C14: Gastos administrativos (fijos) | F14: =-'Gastos Adm y Finanzas'!F29 -> -27485000 | I14: =-'Gastos Adm y Finanzas'!F29 -> -27485000 | L14: =-'Gastos Adm y Finanzas'!F29 -> -27485000 | O14: =-'Gastos Adm y Finanzas'!F29 -> -27485000 | R14: =-'Gastos Adm y Finanzas'!F29 -> -27485000
C15: Utilidades antes de amortizaciones, honorarios intereses e impuesto a las ganancias (EBITDA) | F15: =SUM(F10:F14) -> -18049787 | I15: =SUM(I10:I14) -> 28405150 | L15: =SUM(L10:L14) -> 98087556 | O15: =SUM(O10:O14) -> 1.9099743e+08 | R15: =SUM(R10:R14) -> 330362243
C17: Cuota de amortización | F17: =-'Activo no Corriente'!F25 -> -13910600 | I17: =-'Activo no Corriente'!G25 -> -10728667 | L17: =-'Activo no Corriente'!H25 -> -7546733.3 | O17: =-'Activo no Corriente'!I25 -> -4364800 | R17: =-'Activo no Corriente'!J25 -> -2096533.3
C18: Utilidad antes de honorarios, intereses e impuesto a las ganancias | F18: =F15+F17 -> -31960387 | I18: =I15+I17 -> 17676484 | L18: =L15+L17 -> 90540823 | O18: =O15+O17 -> 1.8663263e+08 | R18: =R15+R17 -> 3.2826571e+08
C19: Honorarios | F19: 0 | I19: =-I15*0.05 -> -1420257.5 | L19: =-L15*0.05 -> -4904377.8 | O19: =-O15*0.05 -> -9549871.5 | R19: =-R15*0.05 -> -16518112
C20: Utilidad antes de intereses (BAII o EBIT) | F20: =SUM(F18:F19) -> -31960387 | I20: =SUM(I18:I19) -> 16256226 | L20: =SUM(L18:L19) -> 85636445 | O20: =SUM(O18:O19) -> 1.7708276e+08 | R20: =SUM(R18:R19) -> 3.117476e+08
C21: Intereses perdidos | F21: =-F75 -> -7948219.7 | I21: =-I75 -> -6358575.8 | L21: =-L75 -> -4768931.8 | O21: =-O75 -> -3179287.9 | R21: =-R75 -> -1589643.9
C22: Intereses ganados | F22: =+E22*F31 -> 0 | I22: =+E22*I31 -> 0 | L22: =+E22*L31 -> 0 | O22: =+E22*O31 -> 0 | R22: =+E22*R31 -> 0
C23: Resultado antes de impuestos (BAI) | F23: =SUM(F20:F22) -> -39908607 | I23: =SUM(I20:I22) -> 9897650.2 | L23: =SUM(L20:L22) -> 80867513 | O23: =SUM(O20:O22) -> 1.7390347e+08 | R23: =SUM(R20:R22) -> 3.1015795e+08
C24: Impuesto a las ganancias | F24: =IF(F23>0,-Consideraciones!$D$17*F23,0) -> 0 | I24: =IF(I23>0,-Consideraciones!$D$17*I23,0) -> -3464177.6 | L24: =IF(L23>0,-Consideraciones!$D$17*L23,0) -> -28303630 | O24: =IF(O23>0,-Consideraciones!$D$17*O23,0) -> -60866215 | R24: =IF(R23>0,-Consideraciones!$D$17*R23,0) -> -1.0855528e+08
C25: Resultado neto del ejercicio (BN) | F25: =SUM(F23:F24) -> -39908607 | I25: =SUM(I23:I24) -> 6433472.6 | L25: =SUM(L23:L24) -> 52563884 | O25: =SUM(O23:O24) -> 1.1303726e+08 | R25: =SUM(R23:R24) -> 2.0160267e+08
C28: Balance General Pro Forma | F28: =+IF(F34/'Costos Variables de Fabricación'!$L$34>Mercado!$H$23,"La cantidad de dias supera la capacidad máx","") | I28: =+IF(I34/'Costos Variables de Fabricación'!$L$34>Mercado!$H$24,"La cantidad de dias supera la capacidad máx","") | L28: =+IF(L34/'Costos Variables de Fabricación'!$L$34>Mercado!$H$25,"La cantidad de dias supera la capacidad máx","") | O28: =+IF(O34/'Costos Variables de Fabricación'!$L$34>Mercado!$H$26,"La cantidad de dias supera la capacidad máx","") | R28: =+IF(R34/'Costos Variables de Fabricación'!$L$34>Mercado!$H$23,"La cantidad de dias supera la capacidad máx","")
D29: Año 0 | F29: Año 1 | I29: Año 2 | L29: Año 3 | O29: Año 4 | R29: Año 5
C30: Cajas y bancos | D30: =+'Capital de trabajo'!D13 -> 17617890 | E30: =D30/$D$41 -> 0.23052465 | F30: =+D30+F89 -> 1836659.6 | G30: =F30*365/F7 -> 4.1768271 | H30: =F30/$F$41 -> 0.031907301 | I30: =F30+I89 -> -6852752.4 | J30: =I30*365/I7 -> -11.131529 | K30: =I30/$F$41 -> -0.11904919 | L30: =I30+L89 -> 23469778 | M30: =L30*365/L7 -> 26.686819 | N30: =L30/$F$41 -> 0.40772785 | O30: =L30+O89 -> 88159163 | P30: =O30*365/O7 -> 71.602346 | Q30: =O30/$F$41 -> 1.5315418 | R30: =O30+R89 -> 2.0540466e+08 | S30: =R30*365/R7 -> 116.77991 | T30: =R30/$R$41 -> 0.68109991
C31: Inversiones financieras | E31: =D31/$D$41 -> 0 | H31: =F31/$F$41 -> 0 | K31: =I31/$F$41 -> 0 | N31: =L31/$F$41 -> 0 | Q31: =O31/$F$41 -> 0 | R31: 1 | T31: =R31/$R$41 -> 3.3158932e-09
C32: Cuentas por cobrar | D32: 0 | E32: =D32/$D$41 -> 0 | F32: =G32*F7/365 -> 13191781 | G32: 30 | H32: =F32/$F$41 -> 0.22917373 | I32: =J32*I7/365 -> 18468493 | J32: 30 | K32: =I32/$F$41 -> 0.32084322 | L32: =M32*L7/365 -> 26383562 | M32: 30 | N32: =L32/$F$41 -> 0.45834745 | O32: =P32*O7/365 -> 36936986 | P32: 30 | Q32: =O32/$F$41 -> 0.64168644 | R32: =S32*R7/365 -> 52767123 | S32: 30 | T32: =R32/$R$41 -> 0.17497015
C33: Crédito Fiscal IVA | D33: ='Activo no Corriente'!E15+'Capital de trabajo'!D7 -> 11157300 | E33: =D33/$D$41 -> 0.14598982 | F33: 0 | H33: =F33/$F$41 -> 0 | I33: 0 | K33: =I33/$F$41 -> 0 | L33: 0 | N33: =L33/$F$41 -> 0 | O33: 0 | Q33: =O33/$F$41 -> 0 | R33: 0 | T33: =R33/$R$41 -> 0
C34: Inventarios | D34: 0 | E34: =D34/$D$41 -> 0 | F34: =G34*F7/365 -> 8794520.5 | G34: 20 | H34: =F34/$F$41 -> 0.15278248 | I34: =J34*I7/365 -> 12312329 | J34: 20 | K34: =I34/$F$41 -> 0.21389548 | L34: =M34*L7/365 -> 17589041 | M34: 20 | N34: =L34/$F$41 -> 0.30556497 | O34: =P34*O7/365 -> 24624658 | P34: 20 | Q34: =O34/$F$41 -> 0.42779096 | R34: =S34*R7/365 -> 35178082 | S34: 20 | T34: =R34/$R$41 -> 0.11664676
C35: Activo corriente | D35: =SUM(D30:D34) -> 28775190 | E35: =D35/$D$41 -> 0.37651447 | F35: =SUM(F30:F34) -> 23822961 | H35: =F35/$F$41 -> 0.41386351 | I35: =SUM(I30:I34) -> 23928070 | K35: =I35/$F$41 -> 0.41568951 | L35: =SUM(L30:L34) -> 67442381 | N35: =L35/$F$41 -> 1.1716403 | O35: =SUM(O30:O34) -> 1.4972081e+08 | Q35: =O35/$F$41 -> 2.6010192 | R35: =SUM(R30:R34) -> 2.9334986e+08 | T35: =R35/$R$41 -> 0.97271683
C39: Bienes de uso | D39: ='Activo no Corriente'!E14 -> 47650000 | E39: =D39/$D$41 -> 0.62348553 | F39: ='Activo no Corriente'!F14 -> 33739400 | H39: =F39/$F$41 -> 0.58613649 | I39: ='Activo no Corriente'!G14 -> 23010733 | K39: =I39/$F$41 -> 0.39975312 | L39: ='Activo no Corriente'!H14 -> 15464000 | N39: =L39/$F$41 -> 0.26864777 | O39: ='Activo no Corriente'!I14 -> 11099200 | Q39: =O39/$F$41 -> 0.19282044 | R39: ='Activo no Corriente'!J14 -> 8228000 | T39: =R39/$R$41 -> 0.02728317
C40: Activo No Corriente | D40: =D39 -> 47650000 | E40: =D40/$D$41 -> 0.62348553 | F40: =F39 -> 33739400 | H40: =F40/$F$41 -> 0.58613649 | I40: =I39 -> 23010733 | K40: =I40/$F$41 -> 0.39975312 | L40: =L39 -> 15464000 | N40: =L40/$F$41 -> 0.26864777 | O40: =O39 -> 11099200 | Q40: =O40/$F$41 -> 0.19282044 | R40: =R39 -> 8228000 | T40: =R40/$R$41 -> 0.02728317
C41: Total Activo | D41: =D40+D35 -> 76425190 | E41: =D41/$D$41 -> 1 | F41: =F40+F35 -> 57562361 | H41: =F41/$F$41 -> 1 | I41: =I40+I35 -> 46938803 | K41: =I41/$F$41 -> 0.81544263 | L41: =L40+L35 -> 82906381 | N41: =L41/$F$41 -> 1.440288 | O41: =O40+O35 -> 1.6082001e+08 | Q41: =O41/$F$41 -> 2.7938397 | R41: =R40+R35 -> 3.0157786e+08 | T41: =R41/$R$41 -> 1
C45: Cuentas por pagar | D45: 0 | E45: =D45/$D$62 -> 0 | F45: =G45*F7/365 -> 13191781 | G45: 30 | H45: =F45/$F$62 -> 0.22917373 | I45: =J45*I7/365 -> 18468493 | J45: 30 | K45: =I45/$F$62 -> 0.32084322 | L45: =M45*L7/365 -> 26383562 | M45: 30 | N45: =L45/$F$62 -> 0.45834745 | O45: =P45*O7/365 -> 36936986 | P45: 30 | Q45: =O45/$F$62 -> 0.64168644 | R45: =S45*R7/365 -> 52767123 | S45: 30 | T45: =R45/$R$62 -> 0.17497015
C46: Impuestos por pagar | D46: 0 | E46: =D46/$D$62 -> 0 | F46: 0 | H46: =F46/$F$62 -> 0 | I46: 0 | K46: =I46/$F$62 -> 0 | L46: 0 | N46: =L46/$F$62 -> 0 | O46: 0 | Q46: =O46/$F$62 -> 0 | R46: 0 | T46: =R46/$R$62 -> 0
C47: Pasivo Corriente | D47: =SUM(D45:D46) -> 0 | E47: =D47/$D$62 -> 0 | F47: =SUM(F45:F46) -> 13191781 | H47: =F47/$F$62 -> 0.22917373 | I47: =SUM(I45:I46) -> 18468493 | K47: =I47/$F$62 -> 0.32084322 | L47: =SUM(L45:L46) -> 26383562 | N47: =L47/$F$62 -> 0.45834745 | O47: =SUM(O45:O46) -> 36936986 | Q47: =O47/$F$62 -> 0.64168644 | R47: =SUM(R45:R46) -> 52767123 | T47: =R47/$R$62 -> 0.17497015
C51: Prestamos Bancarios | D51: ='Cuadro de Usos y Fuentes'!F6 -> 30570076 | E51: =D51/$D$62 -> 0.4 | F51: =+F74 -> 24456061 | H51: =F51/$F$62 -> 0.42486202 | I51: =+I74 -> 18342046 | K51: =I51/$F$62 -> 0.31864651 | L51: =+L74 -> 12228030 | N51: =L51/$F$62 -> 0.21243101 | O51: =+O74 -> 6114015.2 | Q51: =O51/$F$62 -> 0.1062155 | R51: =+R74 -> -1.8626451e-09 | T51: =R51/$R$62 -> 0
C52: Utilidades diferidas | D52: 0 | E52: =D52/$D$62 -> 0 | F52: 0 | H52: =F52/$F$62 -> 0 | K52: =I52/$F$62 -> 0 | N52: =L52/$F$62 -> 0 | Q52: =O52/$F$62 -> 0 | T52: =R52/$R$62 -> 0
C53: Pasivo No Corriente | D53: =SUM(D51:D52) -> 30570076 | E53: =D53/$D$62 -> 0.4 | F53: =SUM(F51:F52) -> 24456061 | H53: =F53/$F$62 -> 0.42486202 | I53: =SUM(I51:I52) -> 18342046 | K53: =I53/$F$62 -> 0.31864651 | L53: =SUM(L51:L52) -> 12228030 | N53: =L53/$F$62 -> 0.21243101 | O53: =SUM(O51:O52) -> 6114015.2 | Q53: =O53/$F$62 -> 0.1062155 | R53: =SUM(R51:R52) -> -1.8626451e-09 | T53: =R53/$R$62 -> 0
C54: Total Pasivo | D54: =D53+D47 -> 30570076 | E54: =D54/$D$62 -> 0.4 | F54: =F53+F47 -> 37647842 | H54: =F54/$F$62 -> 0.65403574 | I54: =I53+I47 -> 36810539 | K54: =I54/$F$62 -> 0.63948973 | L54: =L53+L47 -> 38611592 | N54: =L54/$F$62 -> 0.67077846 | O54: =O53+O47 -> 43051001 | Q54: =O54/$F$62 -> 0.74790194 | R54: =R53+R47 -> 52767123 | T54: =R54/$R$62 -> 0.17497015
C58: Capital | D58: ='Cuadro de Usos y Fuentes'!F7 -> 45855114 | E58: =D58/$D$62 -> 0.6 | F58: =D58 -> 45855114 | H58: =F58/$F$62 -> 0.79661628 | I58: =D58 -> 45855114 | K58: =I58/$F$62 -> 0.79661628 | L58: =D58 -> 45855114 | N58: =L58/$F$62 -> 0.79661628 | O58: =D58 -> 45855114 | Q58: =O58/$F$62 -> 0.79661628 | R58: =D58 -> 45855114 | T58: =R58/$R$62 -> 0.15205066
C59: Resultados no asignados | D59: 0 | E59: =D59/$D$62 -> 0 | F59: =-F67 -> 13968012 | H59: =F59/$F$62 -> 0.24265878 | I59: =+F60-I67 -> -42160322 | K59: =I59/$F$62 -> -0.73242865 | L59: =+I59+I60-L67 -> -54124209 | N59: =L59/$F$62 -> -0.94027083 | O59: =+L59+L60-O67 -> -41123365 | Q59: =O59/$F$62 -> -0.71441415 | R59: =+O59+O60-R67 -> 1352956.9 | T59: =R59/$R$62 -> 0.0044862606
...

Sheet Análisis Económico - Financiero
D2: Año 1 | E2: Año 2 | F2: Año 3 | G2: Año 4 | H2: Año 5
C3: Patrimonio Neto Promedio (PNi+PNf)/2 | D3: =('Balances Pro Forma'!F61+'Balances Pro Forma'!D61)/2 -> 32884817 | E3: =('Balances Pro Forma'!I61+'Balances Pro Forma'!F61)/2 -> 15021392 | F3: =+('Balances Pro Forma'!L61+'Balances Pro Forma'!I61)/2 -> 27211526 | G3: =+('Balances Pro Forma'!O61+'Balances Pro Forma'!L61)/2 -> 81031897 | H3: =+('Balances Pro Forma'!R61+'Balances Pro Forma'!O61)/2 -> 1.8328987e+08
C4: Activo Promedio (Ai + Af)/2 | D4: =+('Balances Pro Forma'!F41+'Balances Pro Forma'!D41)/2 -> 66993775 | E4: =('Balances Pro Forma'!I41+'Balances Pro Forma'!F41)/2 -> 52250582 | F4: =+('Balances Pro Forma'!L41+'Balances Pro Forma'!I41)/2 -> 64922592 | G4: =+('Balances Pro Forma'!O41+'Balances Pro Forma'!L41)/2 -> 1.2186319e+08 | H4: =+('Balances Pro Forma'!R41+'Balances Pro Forma'!O41)/2 -> 2.3119894e+08 | Q4: Mejoró
C5: Beneficio Neto + Intereses*(1-T) | D5: =+'Balances Pro Forma'!F25-'Balances Pro Forma'!F21*(1-'Balances Pro Forma'!E24) -> -31960387 | E5: =+'Balances Pro Forma'!I25-'Balances Pro Forma'!I21*(1-'Balances Pro Forma'!H24) -> 12792048 | F5: =+'Balances Pro Forma'!L25-'Balances Pro Forma'!L21*(1-'Balances Pro Forma'!K24) -> 57332815 | G5: =+'Balances Pro Forma'!O25-'Balances Pro Forma'!O21*(1-'Balances Pro Forma'!N24) -> 1.1621654e+08 | H5: =+'Balances Pro Forma'!R25-'Balances Pro Forma'!R21*(1-'Balances Pro Forma'!Q24) -> 2.0319231e+08 | Q5: Empeoró
C6: ACTIVO CORRIENTE | D6: =+'Balances Pro Forma'!D35 -> 28775190 | E6: =+'Balances Pro Forma'!F35 -> 23822961 | F6: =+'Balances Pro Forma'!I35 -> 23928070 | G6: =+'Balances Pro Forma'!O35 -> 1.4972081e+08 | H6: =+'Balances Pro Forma'!R35 -> 2.9334986e+08
C7: PASIVO CORRIENTE | D7: =+'Balances Pro Forma'!F47 -> 13191781 | E7: =+'Balances Pro Forma'!I47 -> 18468493 | F7: =+'Balances Pro Forma'!L47 -> 26383562 | G7: =+'Balances Pro Forma'!O47 -> 36936986 | H7: =+'Balances Pro Forma'!R47 -> 52767123
Q8: Se Mantiene
C9: Indices Económicos | Q9: Seleccione
D11: Año 1 | E11: Año 2 | F11: Año 3 | G11: Año 4 | H11: Año 5 | J11: Estado
C12: MARGEN SOBRE VENTAS (BN/VENTAS) | D12: =+'Balances Pro Forma'!F25/'Balances Pro Forma'!F7 -> -0.24865176 | E12: =+'Balances Pro Forma'!I25/'Balances Pro Forma'!I7 -> 0.028631387 | F12: =+'Balances Pro Forma'!L25/'Balances Pro Forma'!L7 -> 0.16375042 | G12: =+'Balances Pro Forma'!O25/'Balances Pro Forma'!O7 -> 0.25152928 | H12: =+'Balances Pro Forma'!R25/'Balances Pro Forma'!R7 -> 0.31402285 | J12: Mejoró
C13: ROTACIÓN DEL ACTIVO CORRIENTE | D13: =+'Balances Pro Forma'!F7/'Balances Pro Forma'!F35 -> 6.7371978 | E13: =+'Balances Pro Forma'!I7/'Balances Pro Forma'!I35 -> 9.3906447 | F13: =+'Balances Pro Forma'!L7/'Balances Pro Forma'!L35 -> 4.7596185 | G13: =+'Balances Pro Forma'!O7/'Balances Pro Forma'!O35 -> 3.0015868 | H13: =+'Balances Pro Forma'!R7/'Balances Pro Forma'!R35 -> 2.188513 | I13: veces/año | J13: Empeoró
C14: ROTACIÓN DE CRÉDITOS AL CLIENTE | D14: =+'Balances Pro Forma'!F7/'Balances Pro Forma'!F32 -> 12.166667 | E14: =+'Balances Pro Forma'!I7/'Balances Pro Forma'!I32 -> 12.166667 | F14: =+'Balances Pro Forma'!L7/'Balances Pro Forma'!L32 -> 12.166667 | G14: =+'Balances Pro Forma'!O7/'Balances Pro Forma'!O32 -> 12.166667 | H14: =+'Balances Pro Forma'!R7/'Balances Pro Forma'!R32 -> 12.166667 | I14: veces/año | J14: Se Mantiene
C15: ROTACIÓN DE EXISTENCIAS | D15: =+'Balances Pro Forma'!F7/'Balances Pro Forma'!F34 -> 18.25 | E15: =+'Balances Pro Forma'!I7/'Balances Pro Forma'!I34 -> 18.25 | F15: =+'Balances Pro Forma'!L7/'Balances Pro Forma'!L34 -> 18.25 | G15: =+'Balances Pro Forma'!O7/'Balances Pro Forma'!O34 -> 18.25 | H15: =+'Balances Pro Forma'!R7/'Balances Pro Forma'!R34 -> 18.25 | I15: veces/año | J15: Se Mantiene
C16: ROTACIÓN DEL ACTIVO (VENTAS / ACTIVO PROMEDIO) | D16: ='Balances Pro Forma'!F7/D4 -> 2.395745 | E16: ='Balances Pro Forma'!I7/E4 -> 4.3004306 | F16: ='Balances Pro Forma'!L7/F4 -> 4.9443497 | G16: ='Balances Pro Forma'!O7/G4 -> 3.6877419 | H16: ='Balances Pro Forma'!R7/H4 -> 2.7768294 | J16: Mejoró
C17: ROTACIÓN DEL PATRIMONIO NETO PROMEDIO | D17: =+'Balances Pro Forma'!F7/D3 -> 4.8806719 | E17: ='Balances Pro Forma'!I7/E3 -> 14.958667 | F17: ='Balances Pro Forma'!L7/F3 -> 11.796472 | G17: ='Balances Pro Forma'!O7/G3 -> 5.5459642 | H17: =+'Balances Pro Forma'!R7/H3 -> 3.5026485 | I17: veces/año | J17: Mejoró
C18: EFECTO PALANCA | D18: =D19/D20 -> 2.5438621 | E18: =E19/E20 -> 1.7493887 | F18: =F19/F20 -> 2.1873945 | G18: =G19/G20 -> 1.4627503 | H18: =H19/H20 -> 1.2515159 | J18: Empeoró
C19: ROE | D19: =D12*D16*D21 -> -1.2135876 | E19: =E12*E16*E21 -> 0.42828739 | F19: =F12*F16*F21 -> 1.9316771 | G19: =G12*G16*G21 -> 1.3949724 | H19: =H12*H16*H21 -> 1.0999117 | J19: Mejoró
C20: ROA | D20: =D5/D4 -> -0.47706503 | E20: =E5/E4 -> 0.24482117 | F20: =F5/F4 -> 0.88309499 | G20: =G5/G4 -> 0.95366403 | H20: =H5/H4 -> 0.87886354 | J20: Mejoró
C21: APALANCAMIENTO (ACTIVO PROMEDIO / PATRIMONIO NETO PROM.) | D21: =D4/D3 -> 2.0372251 | E21: =E4/E3 -> 3.4784115 | F21: =F4/F3 -> 2.385849 | G21: =G4/G3 -> 1.5038917 | H21: =H4/H3 -> 1.2613841 | J21: Mejoró
C23: Conclusión
C27: Indices Financieros
D29: Año 1 | E29: Año 2 | F29: Año 3 | G29: Año 4 | H29: Año 5 | I29: Estado
C30: INDICE DE SOLVENCIA = AC / PC | D30: =+D6/D7 -> 2.1812968 | E30: =+E6/E7 -> 1.2899245 | F30: =+F6/F7 -> 0.90693099 | G30: =+G6/G7 -> 4.0534115 | H30: =+H6/H7 -> 5.5593302 | I30: Mejoró
C31: INDICE DE LIQUIDÉZ (IL)= (CyB+CREDITO A CLIENTES)/(PC) | D31: =+('Balances Pro Forma'!F30+'Balances Pro Forma'!F32)/D7 -> 1.1392276 | E31: =+('Balances Pro Forma'!I30+'Balances Pro Forma'!I32)/E7 -> 0.62894903 | F31: =+('Balances Pro Forma'!L30+'Balances Pro Forma'!L32)/F7 -> 1.8895606 | G31: =+('Balances Pro Forma'!O30+'Balances Pro Forma'!O32)/G7 -> 3.3867449 | H31: =+('Balances Pro Forma'!R30+'Balances Pro Forma'!R32)/H7 -> 4.8926635 | I31: Mejoró
